Workbook

Sheet Lisez-moi
A1: AutoFlow Pro — base de données de l'agence
A3: Données FICTIVES générées le 25/09/2026 (graine 2026)
A4: Période : 01/07/2026 → 30/09/2026 (3 mois, haute saison)
A5: 38 véhicules · 200 clients · 534 locations · 219 dépenses · 24 rendez-vous.
A6: Tarifs basés sur les prix réels du marché marocain 2025-2026 (RAKB, OneClickDrive, Avito, agences Rabat).
A7: Importer ce fichier dans AutoFlow : Administration → Données Excel. Les colonnes vertes sont calculées.

Sheet Guide
A1: FEUILLE | B1: COLONNE | C1: DESCRIPTION
A2: Locations | B2: MATRICULE | C2: Plaque du véhicule (doit exister dans Flotte)
A3: Locations | B3: CIN | C3: CIN marocaine (ex. AB123456) ou passeport (ex. XK1234567)
A4: Locations | B4: PRIX_JOUR | C4: Prix facturé par jour, en MAD
A5: Locations | B5: DATE_SORTIE | C5: Le véhicule quitte l'agence (début de location)
A6: Locations | B6: DATE_ENTREE | C6: Le véhicule revient à l'agence (fin de location)
A7: Locations | B7: PERIODE | C7: Calculé : DATE_ENTREE − DATE_SORTIE (jours, minimum 1)
A8: Locations | B8: MONTANT | C8: Calculé : PRIX_JOUR × PERIODE
A9: Locations | B9: DISPONIBILITE | C9: Calculé : À venir / En cours / Terminée selon la date du jour
A10: Flotte | B10: DISPONIBILITE | C10: Calculé : Disponible / Louée / Maintenance aujourd'hui
A11: Depenses | B11: MATRICULE | C11: Vide = frais généraux de l'agence (loyer, salaires…)
A12: Depenses | B12: CATEGORIE | C12: Liste fermée : Leasing, Assurance, Vignette, Vidange, Pneus, Réparation, Lavage, Visite technique, Carburant, Loyer, Salaires, Électricité & eau, Internet & téléphone, Marketing, Comptabilité, Logiciel
... A14: — | B14: Colonnes vertes | C14: Formules : ne pas saisir. AutoFlow les recalcule à l'import.

Sheet Locations
A1: N_LOCATION | B1: MATRICULE | C1: CIN | D1: PRIX_JOUR | E1: DATE_SORTIE | F1: DATE_ENTREE | G1: PERIODE | H1: MONTANT | I1: DISPONIBILITE | J1: CANAL | K1: STATUT
A2: L-00001 | B2: 49965-H-1 | C2: G1943814 | D2: 1050 | E2: 46204 | F2: 46211 | G2: =MAX(1,F2-E2) | H2: =D2*G2 | I2: =IF(TODAY()<E2,"À venir",IF(TODAY()<F2,"En cours","Terminée")) | J2: WhatsApp | K2: Terminée
A3: L-00002 | B3: 54616-W-1 | C3: PA5242299 | D3: 190 | E3: 46204 | F3: 46225 | G3: =MAX(1,F3-E3) | H3: =D3*G3 | I3: =IF(TODAY()<E3,"À venir",IF(TODAY()<F3,"En cours","Terminée")) | J3: Booking.com | K3: Terminée
A4: L-00003 | B4: 74343-B-1 | C4: CD761106 | D4: 260 | E4: 46204 | F4: 46211 | G4: =MAX(1,F4-E4) | H4: =D4*G4 | I4: =IF(TODAY()<E4,"À venir",IF(TODAY()<F4,"En cours","Terminée")) | J4: Facebook | K4: Terminée
A5: L-00004 | B5: 76545-W-1 | C5: EE722487 | D5: 720 | E5: 46204 | F5: 46207 | G5: =MAX(1,F5-E5) | H5: =D5*G5 | I5: =IF(TODAY()<E5,"À venir",IF(TODAY()<F5,"En cours","Terminée")) | J5: Facebook | K5: Terminée
A6: L-00005 | B6: 81442-B-1 | C6: G6378219 | D6: 490 | E6: 46204 | F6: 46208 | G6: =MAX(1,F6-E6) | H6: =D6*G6 | I6: =IF(TODAY()<E6,"À venir",IF(TODAY()<F6,"En cours","Terminée")) | J6: Facebook | K6: Terminée
A7: L-00006 | B7: 85684-A-1 | C7: AD941277 | D7: 280 | E7: 46204 | F7: 46207 | G7: =MAX(1,F7-E7) | H7: =D7*G7 | I7: =IF(TODAY()<E7,"À venir",IF(TODAY()<F7,"En cours","Terminée")) | J7: Site web | K7: Terminée
A8: L-00007 | B8: 88664-D-1 | C8: BE195212 | D8: 380 | E8: 46204 | F8: 46209 | G8: =MAX(1,F8-E8) | H8: =D8*G8 | I8: =IF(TODAY()<E8,"À venir",IF(TODAY()<F8,"En cours","Terminée")) | J8: Comptoir | K8: Terminée
A9: L-00008 | B9: 88778-A-1 | C9: DA228644 | D9: 230 | E9: 46204 | F9: 46218 | G9: =MAX(1,F9-E9) | H9: =D9*G9 | I9: =IF(TODAY()<E9,"À venir",IF(TODAY()<F9,"En cours","Terminée")) | J9: Téléphone | K9: Terminée
A10: L-00009 | B10: 94626-B-1 | C10: BK494164 | D10: 1060 | E10: 46204 | F10: 46218 | G10: =MAX(1,F10-E10) | H10: =D10*G10 | I10: =IF(TODAY()<E10,"À venir",IF(TODAY()<F10,"En cours","Terminée")) | J10: Site web | K10: Terminée
A11: L-00010 | B11: 96667-D-1 | C11: A4460128 | D11: 1030 | E11: 46204 | F11: 46207 | G11: =MAX(1,F11-E11) | H11: =D11*G11 | I11: =IF(TODAY()<E11,"À venir",IF(TODAY()<F11,"En cours","Terminée")) | J11: WhatsApp | K11: Terminée
A12: L-00011 | B12: 22080-H-1 | C12: CD196457 | D12: 340 | E12: 46205 | F12: 46210 | G12: =MAX(1,F12-E12) | H12: =D12*G12 | I12: =IF(TODAY()<E12,"À venir",IF(TODAY()<F12,"En cours","Terminée")) | J12: Instagram | K12: Terminée
A13: L-00012 | B13: 22394-A-1 | C13: DA287805 | D13: 390 | E13: 46205 | F13: 46210 | G13: =MAX(1,F13-E13) | H13: =D13*G13 | I13: =IF(TODAY()<E13,"À venir",IF(TODAY()<F13,"En cours","Terminée")) | J13: WhatsApp | K13: Terminée
... A535: L-00534 | B535: 54616-W-1 | C535: G5643699 | D535: 180 | E535: 46385 | F535: 46389 | G535: =MAX(1,F535-E535) | H535: =D535*G535 | I535: =IF(TODAY()<E535,"À venir",IF(TODAY()<F535,"En cours","Terminée")) | J535: Booking.com | K535: Réservée

Sheet Flotte
A1: CODE | B1: MATRICULE | C1: MODELE | D1: CATEGORIE | E1: BOITE | F1: AGENCE | G1: PRIX_JOUR | H1: STATUT | I1: FIN_MAINTENANCE | J1: MISE_EN_CIRCULATION | K1: KM | L1: ASSURANCE_EXPIRE | M1: VISITE_TECHNIQUE_EXPIRE | N1: DISPONIBILITE
A2: CIT-01 | B2: 88778-A-1 | C2: Dacia Sandero | D2: citadine | E2: manuelle | F2: Agdal | G2: 200 | H2: active | J2: 43633 | K2: 234605 | L2: 46315 | M2: 46334 | N2: =IF(H2="maintenance","Maintenance",IF(COUNTIFS(Locations!B:B,B2,Locations!E:E,"<="&TODAY(),Locations!F:F,">"&TODAY())>0,"Louée","Disponible"))
A3: CIT-02 | B3: 74343-B-1 | C3: Dacia Sandero Stepway | D3: citadine | E3: manuelle | F3: Hay Riad | G3: 230 | H3: active | J3: 45183 | K3: 91236 | L3: 46383 | N3: =IF(H3="maintenance","Maintenance",IF(COUNTIFS(Locations!B:B,B3,Locations!E:E,"<="&TODAY(),Locations!F:F,">"&TODAY())>0,"Louée","Disponible"))
A4: CIT-03 | B4: 47649-D-1 | C4: Renault Clio 5 | D4: citadine | E4: manuelle | F4: Agdal | G4: 250 | H4: active | J4: 45146 | K4: 63021 | L4: 46299 | N4: =IF(H4="maintenance","Maintenance",IF(COUNTIFS(Locations!B:B,B4,Locations!E:E,"<="&TODAY(),Locations!F:F,">"&TODAY())>0,"Louée","Disponible"))
A5: CIT-04 | B5: 62064-H-1 | C5: Renault Clio 5 | D5: citadine | E5: automatique | F5: Aéroport Rabat-Salé | G5: 280 | H5: active | J5: 43678 | K5: 218145 | L5: 46372 | M5: 46363 | N5: =IF(H5="maintenance","Maintenance",IF(COUNTIFS(Locations!B:B,B5,Locations!E:E,"<="&TODAY(),Locations!F:F,">"&TODAY())>0,"Louée","Disponible"))
A6: CIT-05 | B6: 54616-W-1 | C6: Hyundai i10 | D6: citadine | E6: manuelle | F6: Agdal | G6: 180 | H6: active | J6: 44359 | K6: 160620 | L6: 46373 | M6: 46350 | N6: =IF(H6="maintenance","Maintenance",IF(COUNTIFS(Locations!B:B,B6,Locations!E:E,"<="&TODAY(),Locations!F:F,">"&TODAY())>0,"Louée","Disponible"))
A7: CIT-06 | B7: 85684-A-1 | C7: Hyundai i20 | D7: citadine | E7: manuelle | F7: Hay Riad | G7: 220 | H7: active | J7: 43726 | K7: 167235 | L7: 46309 | M7: 46347 | N7: =IF(H7="maintenance","Maintenance",IF(COUNTIFS(Locations!B:B,B7,Locations!E:E,"<="&TODAY(),Locations!F:F,">"&TODAY())>0,"Louée","Disponible"))
A8: CIT-07 | B8: 62268-B-1 | C8: Peugeot 208 | D8: citadine | E8: manuelle | F8: Agdal | G8: 260 | H8: active | J8: 44224 | K8: 165032 | L8: 46341 | M8: 46359 | N8: =IF(H8="maintenance","Maintenance",IF(COUNTIFS(Locations!B:B,B8,Locations!E:E,"<="&TODAY(),Locations!F:F,">"&TODAY())>0,"Louée","Disponible"))
A9: CIT-08 | B9: 88664-D-1 | C9: Peugeot 208 | D9: citadine | E9: automatique | F9: Aéroport Rabat-Salé | G9: 300 | H9: active | J9: 45185 | K9: 94314 | L9: 46343 | N9: =IF(H9="maintenance","Maintenance",IF(COUNTIFS(Locations!B:B,B9,Locations!E:E,"<="&TODAY(),Locations!F:F,">"&TODAY())>0,"Louée","Disponible"))
A10: CIT-09 | B10: 77893-H-1 | C10: Fiat 500 | D10: citadine | E10: manuelle | F10: Hay Riad | G10: 250 | H10: active | J10: 44759 | K10: 98064 | L10: 46345 | M10: 46373 | N10: =IF(H10="maintenance","Maintenance",IF(COUNTIFS(Locations!B:B,B10,Locations!E:E,"<="&TODAY(),Locations!F:F,">"&TODAY())>0,"Louée","Disponible"))
A11: CIT-10 | B11: 91567-W-1 | C11: Kia Picanto | D11: citadine | E11: manuelle | F11: Agdal | G11: 190 | H11: active | J11: 43746 | K11: 208109 | L11: 46318 | M11: 46349 | N11: =IF(H11="maintenance","Maintenance",IF(COUNTIFS(Locations!B:B,B11,Locations!E:E,"<="&TODAY(),Locations!F:F,">"&TODAY())>0,"Louée","Disponible"))
A12: CIT-11 | B12: 69873-A-1 | C12: Toyota Yaris | D12: citadine | E12: automatique | F12: Hay Riad | G12: 290 | H12: active | J12: 44778 | K12: 108673 | L12: 46302 | M12: 46347 | N12: =IF(H12="maintenance","Maintenance",IF(COUNTIFS(Locations!B:B,B12,Locations!E:E,"<="&TODAY(),Locations!F:F,">"&TODAY())>0,"Louée","Disponible"))
A13: CIT-12 | B13: 83373-B-1 | C13: Volkswagen Polo | D13: citadine | E13: manuelle | F13: Aéroport Rabat-Salé | G13: 270 | H13: active | J13: 45527 | K13: 66786 | L13: 46365 | N13: =IF(H13="maintenance","Maintenance",IF(COUNTIFS(Locations!B:B,B13,Locations!E:E,"<="&TODAY(),Locations!F:F,">"&TODAY())>0,"Louée","Disponible"))
A14: BER-01 | B14: 72769-D-1 | C14: Dacia Logan | D14: berline | E14: manuelle | F14: Agdal | G14: 180 | H14: active | J14: 44875 | K14: 104972 | L14: 46373 | N14: =IF(H14="maintenance","Maintenance",IF(COUNTIFS(Locations!B:B,B14,Locations!E:E,"<="&TODAY(),Locations!F:F,">"&TODAY())>0,"Louée","Disponible"))
A15: BER-02 | B15: 95936-H-1 | C15: Renault Mégane | D15: berline | E15: automatique | F15: Hay Riad | G15: 380 | H15: active | J15: 44749 | K15: 100632 | L15: 46327 | M15: 46331 | N15: =IF(H15="maintenance","Maintenance",IF(COUNTIFS(Locations!B:B,B15,Locations!E:E,"<="&TODAY(),Locations!F:F,">"&TODAY())>0,"Louée","Disponible"))
A16: BER-03 | B16: 36193-W-1 | C16: Peugeot 308 | D16: berline | E16: automatique | F16: Agdal | G16: 400 | H16: active | J16: 45164 | K16: 82537 | L16: 46338 | N16: =IF(H16="maintenance","Maintenance",IF(COUNTIFS(Locations!B:B,B16,Locations!E:E,"<="&TODAY(),Locations!F:F,">"&TODAY())>0,"Louée","Disponible"))
A17: BER-04 | B17: 97018-A-1 | C17: Hyundai Accent | D17: berline | E17: automatique | F17: Hay Riad | G17: 350 | H17: active | J17: 44546 | K17: 124404 | L17: 46310 | M17: 46374 | N17: =IF(H17="maintenance","Maintenance",IF(COUNTIFS(Locations!B:B,B17,Locations!E:E,"<="&TODAY(),Locations!F:F,">"&TODAY())>0,"Louée","Disponible"))
A18: BER-05 | B18: 33992-B-1 | C18: Toyota Corolla | D18: berline | E18: automatique | F18: Agdal | G18: 420 | H18: active | J18: 43596 | K18: 191322 | L18: 46310 | M18: 46371 | N18: =IF(H18="maintenance","Maintenance",IF(COUNTIFS(Locations!B:B,B18,Locations!E:E,"<="&TODAY(),Locations!F:F,">"&TODAY())>0,"Louée","Disponible"))
A19: BER-06 | B19: 75329-D-1 | C19: Skoda Octavia | D19: berline | E19: automatique | F19: Aéroport Rabat-Salé | G19: 450 | H19: active | J19: 44911 | K19: 121220 | L19: 46365 | N19: =IF(H19="maintenance","Maintenance",IF(COUNTIFS(Locations!B:B,B19,Locations!E:E,"<="&TODAY(),Locations!F:F,">"&TODAY())>0,"Louée","Disponible"))
A20: BER-07 | B20: 22080-H-1 | C20: Fiat Tipo | D20: berline | E20: manuelle | F20: Agdal | G20: 280 | H20: active | J20: 44234 | K20: 166873 | L20: 46331 | M20: 46357 | N20: =IF(H20="maintenance","Maintenance",IF(COUNTIFS(Locations!B:B,B20,Locations!E:E,"<="&TODAY(),Locations!F:F,">"&TODAY())>0,"Louée","Disponible"))
A21: BER-08 | B21: 25835-W-1 | C21: Volkswagen Jetta | D21: berline | E21: automatique | F21: Hay Riad | G21: 480 | H21: active | J21: 43696 | K21: 192294 | L21: 46315 | M21: 46334 | N21: =IF(H21="maintenance","Maintenance",IF(COUNTIFS(Locations!B:B,B21,Locations!E:E,"<="&TODAY(),Locations!F:F,">"&TODAY())>0,"Louée","Disponible"))
A22: SUV-01 | B22: 97618-A-1 | C22: Dacia Duster | D22: suv | E22: manuelle | F22: Agdal | G22: 400 | H22: active | J22: 44951 | K22: 99254 | L22: 46303 | N22: =IF(H22="maintenance","Maintenance",IF(COUNTIFS(Locations!B:B,B22,Locations!E:E,"<="&TODAY(),Locations!F:F,">"&TODAY())>0,"Louée","Disponible"))
A23: SUV-02 | B23: 85272-B-1 | C23: Dacia Duster | D23: suv | E23: automatique | F23: Hay Riad | G23: 450 | H23: active | J23: 45448 | K23: 46461 | L23: 46375 | N23: =IF(H23="maintenance","Maintenance",IF(COUNTIFS(Locations!B:B,B23,Locations!E:E,"<="&TODAY(),Locations!F:F,">"&TODAY())>0,"Louée","Disponible"))
A24: SUV-03 | B24: 71994-D-1 | C24: Hyundai Tucson | D24: suv | E24: automatique | F24: Agdal | G24: 550 | H24: active | J24: 44919 | K24: 120391 | L24: 46364 | N24: =IF(H24="maintenance","Maintenance",IF(COUNTIFS(Locations!B:B,B24,Locations!E:E,"<="&TODAY(),Locations!F:F,">"&TODAY())>0,"Louée","Disponible"))
A25: SUV-04 | B25: 21066-H-1 | C25: Hyundai Creta | D25: suv | E25: automatique | F25: Hay Riad | G25: 500 | H25: active | J25: 45005 | K25: 110072 | L25: 46366 | N25: =IF(H25="maintenance","Maintenance",IF(COUNTIFS(Locations!B:B,B25,Locations!E:E,"<="&TODAY(),Locations!F:F,">"&TODAY())>0,"Louée","Disponible"))
A26: SUV-05 | B26: 76545-W-1 | C26: Kia Sportage | D26: suv | E26: automatique | F26: Agdal | G26: 600 | H26: active | J26: 44871 | K26: 124484 | L26: 46366 | N26: =IF(H26="maintenance","Maintenance",IF(COUNTIFS(Locations!B:B,B26,Locations!E:E,"<="&TODAY(),Locations!F:F,">"&TODAY())>0,"Louée","Disponible"))
A27: SUV-06 | B27: 23911-A-1 | C27: Peugeot 3008 | D27: suv | E27: automatique | F27: Aéroport Rabat-Salé | G27: 650 | H27: maintenance | I27: 46310 | J27: 44768 | K27: 91622 | L27: 46301 | M27: 46357 | N27: =IF(H27="maintenance","Maintenance",IF(COUNTIFS(Locations!B:B,B27,Locations!E:E,"<="&TODAY(),Locations!F:F,">"&TODAY())>0,"Louée","Disponible"))
A28: SUV-07 | B28: 76897-B-1 | C28: Renault Kadjar | D28: suv | E28: automatique | F28: Agdal | G28: 520 | H28: active | J28: 44594 | K28: 142774 | L28: 46368 | M28: 46327 | N28: =IF(H28="maintenance","Maintenance",IF(COUNTIFS(Locations!B:B,B28,Locations!E:E,"<="&TODAY(),Locations!F:F,">"&TODAY())>0,"Louée","Disponible"))
A29: SUV-08 | B29: 84923-D-1 | C29: Volkswagen T-Roc | D29: suv | E29: automatique | F29: Hay Riad | G29: 580 | H29: active | J29: 44734 | K29: 102117 | L29: 46330 | M29: 46371 | N29: =IF(H29="maintenance","Maintenance",IF(COUNTIFS(Locations!B:B,B29,Locations!E:E,"<="&TODAY(),Locations!F:F,">"&TODAY())>0,"Louée","Disponible"))
A30: PRE-01 | B30: 91702-H-1 | C30: Mercedes Classe A | D30: premium | E30: automatique | F30: Agdal | G30: 800 | H30: active | J30: 44990 | K30: 98402 | L30: 46309 | N30: =IF(H30="maintenance","Maintenance",IF(COUNTIFS(Locations!B:B,B30,Locations!E:E,"<="&TODAY(),Locations!F:F,">"&TODAY())>0,"Louée","Disponible"))
A31: PRE-02 | B31: 35623-W-1 | C31: Mercedes Classe C | D31: premium | E31: automatique | F31: Aéroport Rabat-Salé | G31: 1200 | H31: active | J31: 44428 | K31: 117615 | L31: 46359 | M31: 46358 | N31: =IF(H31="maintenance","Maintenance",IF(COUNTIFS(Locations!B:B,B31,Locations!E:E,"<="&TODAY(),Locations!F:F,">"&TODAY())>0,"Louée","Disponible"))
A32: PRE-03 | B32: 69221-A-1 | C32: BMW Série 3 | D32: premium | E32: automatique | F32: Agdal | G32: 1100 | H32: active | J32: 45353 | K32: 72793 | L32: 46296 | N32: =IF(H32="maintenance","Maintenance",IF(COUNTIFS(Locations!B:B,B32,Locations!E:E,"<="&TODAY(),Locations!F:F,">"&TODAY())>0,"Louée","Disponible"))
A33: PRE-04 | B33: 94626-B-1 | C33: Audi A3 | D33: premium | E33: automatique | F33: Hay Riad | G33: 900 | H33: active | J33: 45398 | K33: 71255 | L33: 46300 | N33: =IF(H33="maintenance","Maintenance",IF(COUNTIFS(Locations!B:B,B33,Locations!E:E,"<="&TODAY(),Locations!F:F,">"&TODAY())>0,"Louée","Disponible"))
A34: 4X4-01 | B34: 96667-D-1 | C34: Toyota Hilux | D34: 4x4 | E34: manuelle | F34: Hay Riad | G34: 800 | H34: active | J34: 45042 | K34: 107194 | L34: 46301 | N34: =IF(H34="maintenance","Maintenance",IF(COUNTIFS(Locations!B:B,B34,Locations!E:E,"<="&TODAY(),Locations!F:F,">"&TODAY())>0,"Louée","Disponible"))
A35: 4X4-02 | B35: 49965-H-1 | C35: Ford Ranger | D35: 4x4 | E35: automatique | F35: Aéroport Rabat-Salé | G35: 900 | H35: active | J35: 44021 | K35: 158574 | L35: 46354 | M35: 46339 | N35: =IF(H35="maintenance","Maintenance",IF(COUNTIFS(Locations!B:B,B35,Locations!E:E,"<="&TODAY(),Locations!F:F,">"&TODAY())>0,"Louée","Disponible"))
A36: UTL-01 | B36: 71302-W-1 | C36: Renault Kangoo | D36: utilitaire | E36: manuelle | F36: Hay Riad | G36: 350 | H36: active | J36: 43988 | K36: 147835 | L36: 46351 | M36: 46366 | N36: =IF(H36="maintenance","Maintenance",IF(COUNTIFS(Locations!B:B,B36,Locations!E:E,"<="&TODAY(),Locations!F:F,">"&TODAY())>0,"Louée","Disponible"))
A37: UTL-02 | B37: 22394-A-1 | C37: Fiat Doblo | D37: utilitaire | E37: manuelle | F37: Agdal | G37: 320 | H37: active | J37: 43999 | K37: 164658 | L37: 46298 | M37: 46383 | N37: =IF(H37="maintenance","Maintenance",IF(COUNTIFS(Locations!B:B,B37,Locations!E:E,"<="&TODAY(),Locations!F:F,">"&TODAY())>0,"Louée","Disponible"))
A38: UTL-03 | B38: 81442-B-1 | C38: Renault Express | D38: utilitaire | E38: manuelle | F38: Aéroport Rabat-Salé | G38: 380 | H38: active | J38: 43922 | K38: 209280 | L38: 46347 | M38: 46370 | N38: =IF(H38="maintenance","Maintenance",IF(COUNTIFS(Locations!B:B,B38,Locations!E:E,"<="&TODAY(),Locations!F:F,">"&TODAY())>0,"Louée","Disponible"))
A39: UTL-04 | B39: 83662-D-1 | C39: Citroën Berlingo | D39: utilitaire | E39: manuelle | F39: Agdal | G39: 360 | H39: active | J39: 45352 | K39: 63144 | L39: 46307 | N39: =IF(H39="maintenance","Maintenance",IF(COUNTIFS(Locations!B:B,B39,Locations!E:E,"<="&TODAY(),Locations!F:F,">"&TODAY())>0,"Louée","Disponible"))

Sheet Clients
A1: CIN | B1: NOM | C1: TELEPHONE | D1: VIP | E1: NOTES | F1: CODE
A2: DA850793 | B2: Hind El Fassi | C2: 07 81 82 37 82 | D2: oui | E2: Client entreprise (facture) | F2: C-001
A3: AE201114 | B3: Khadija El Fassi | C3: 07 31 23 97 17 | D3: oui | E3: Préfère WhatsApp | F3: C-002
A4: G5643699 | B4: Reda Bouzidi | C4: 06 47 50 30 43 | D4: oui | E4: Client entreprise (facture) | F4: C-003
A5: DE1258872 | B5: Fatou Rossi | C5: 06 22 40 12 49 | D5: non | F5: C-004
A6: IT1637716 | B6: Ingrid Svensson | C6: 07 50 87 37 86 | D6: non | E6: Paiement à la remise des clés | F6: C-005
A7: G9409777 | B7: Nadia Bouazza | C7: 07 59 47 55 17 | D7: oui | E7: Demande souvent l'aéroport | F7: C-006
A8: AA411366 | B8: Oussama Sqalli | C8: 07 50 84 12 79 | D8: oui | E8: Préfère WhatsApp | F8: C-007
A9: DA228644 | B9: Anas Berrada | C9: 06 14 26 76 55 | D9: oui | E9: Client entreprise (facture) | F9: C-008
A10: DE7444227 | B10: Luca Svensson | C10: 07 40 63 94 38 | D10: non | F10: C-009
A11: CD516136 | B11: Ismail Bouazza | C11: 07 28 39 12 12 | D11: oui | E11: Client entreprise (facture) | F11: C-010
A12: EE722487 | B12: Mounir Idrissi | C12: 06 32 80 14 93 | D12: oui | E12: Client régulier | F12: C-011
A13: G1943814 | B13: Badr El Harrak | C13: 06 90 41 70 17 | D13: oui | F13: C-012
A14: BK841625 | B14: Ines El Idrissi | C14: 07 39 81 45 53 | D14: non | F14: C-013
A15: BE926937 | B15: Jamal El Amrani | C15: 07 34 30 90 62 | D15: non | F15: C-014
A16: CD836465 | B16: Soufiane Kadiri | C16: 07 14 91 32 20 | D16: non | E16: Client entreprise (facture) | F16: C-015
A17: AA119243 | B17: Khadija Tahiri | C17: 06 99 84 49 83 | D17: non | F17: C-016
A18: EE793915 | B18: Badr Moussaoui | C18: 06 75 23 20 28 | D18: non | E18: Demande souvent l'aéroport | F18: C-017
A19: DA794435 | B19: Omar Benchekroun | C19: 06 30 47 47 79 | D19: non | E19: Client entreprise (facture) | F19: C-018
A20: EE109907 | B20: Hind Benchekroun | C20: 07 64 55 78 31 | D20: non | F20: C-019
A21: YA1476776 | B21: Paolo García | C21: 06 75 95 92 10 | D21: non | E21: Préfère WhatsApp | F21: C-020
A22: YA5163351 | B22: Marie Schmidt | C22: 06 23 51 72 23 | D22: non | F22: C-021
A23: G8958792 | B23: Wiam El Fassi | C23: 07 25 81 76 41 | D23: non | E23: Préfère WhatsApp | F23: C-022
A24: AA916889 | B24: Soufiane Tazi | C24: 06 73 49 43 94 | D24: non | F24: C-023
A25: G9274426 | B25: Anass Ouazzani | C25: 07 50 32 35 69 | D25: non | F25: C-024
A26: G7873623 | B26: Samira Moussaoui | C26: 07 37 29 66 82 | D26: non | F26: C-025
A27: AE982041 | B27: Anas Ouazzani | C27: 07 43 28 79 90 | D27: non | E27: Client entreprise (facture) | F27: C-026
A28: AA380924 | B28: Karima El Harrak | C28: 07 83 68 91 61 | D28: non | E28: Demande souvent l'aéroport | F28: C-027
A29: GB2593937 | B29: Paolo Diallo | C29: 07 96 91 95 79 | D29: non | F29: C-028
A30: BK859626 | B30: Oussama Bennani | C30: 06 11 44 81 99 | D30: non | E30: Client entreprise (facture) | F30: C-029
A31: BE992685 | B31: Chaimae Naciri | C31: 07 53 11 14 38 | D31: non | F31: C-030
A32: AD929155 | B32: Kenza Alaoui | C32: 07 75 45 89 90 | D32: non | E32: Préfère WhatsApp | F32: C-031
A33: AB3614343 | B33: Carlos Dupont | C33: 07 38 69 36 87 | D33: non | F33: C-032
A34: CD814227 | B34: Abdel Tahiri | C34: 06 23 13 44 63 | D34: non | F34: C-033
A35: BE789842 | B35: Meryem Regragui | C35: 07 53 54 50 87 | D35: non | E35: Paiement à la remise des clés | F35: C-034
A36: EE613807 | B36: Souad Bennani | C36: 06 12 71 56 42 | D36: non | E36: Paiement à la remise des clés | F36: C-035
A37: AD710001 | B37: Rachid Sqalli | C37: 06 62 18 92 94 | D37: non | F37: C-036
A38: DA195125 | B38: Zineb Rami | C38: 07 72 50 94 53 | D38: non | E38: Préfère WhatsApp | F38: C-037
A39: AE653640 | B39: Hanane Berrada | C39: 07 90 23 87 37 | D39: non | F39: C-038
A40: CD232629 | B40: Taha Sefrioui | C40: 06 44 72 27 81 | D40: non | E40: Préfère WhatsApp | F40: C-039
...

Sheet Depenses
A1: DATE | B1: MATRICULE | C1: CATEGORIE | D1: MONTANT | E1: FOURNISSEUR | F1: NOTE
A2: 46204 | C2: Loyer | D2: 12000 | E2: SCI Agdal | F2: Agence Agdal
A3: 46204 | C3: Loyer | D3: 7000 | E3: Particulier | F3: Point Hay Riad
A4: 46204 | C4: Loyer | D4: 5000 | E4: ONDA | F4: Comptoir aéroport
A5: 46206 | C5: Logiciel | D5: 400 | E5: Hébergement AutoFlow | F5: VPS + domaine
A6: 46206 | B6: 36193-W-1 | C6: Carburant | D6: 600 | E6: Afriquia | F6: Plein avant livraison aéroport
A7: 46208 | B7: 21066-H-1 | C7: Leasing | D7: 3750 | E7: Wafasalaf LOA | F7: Échéance 07/2026
A8: 46208 | B8: 36193-W-1 | C8: Leasing | D8: 3000 | E8: Wafasalaf LOA | F8: Échéance 07/2026
A9: 46208 | B9: 47649-D-1 | C9: Leasing | D9: 1870 | E9: Wafasalaf LOA | F9: Échéance 07/2026
A10: 46208 | B10: 69221-A-1 | C10: Leasing | D10: 8250 | E10: Wafasalaf LOA | F10: Échéance 07/2026
A11: 46208 | B11: 74343-B-1 | C11: Leasing | D11: 1720 | E11: Wafasalaf LOA | F11: Échéance 07/2026
A12: 46208 | B12: 83373-B-1 | C12: Leasing | D12: 2020 | E12: Wafasalaf LOA | F12: Échéance 07/2026
A13: 46208 | B13: 83662-D-1 | C13: Leasing | D13: 2700 | E13: Wafasalaf LOA | F13: Échéance 07/2026
A14: 46208 | B14: 85272-B-1 | C14: Leasing | D14: 3370 | E14: Wafasalaf LOA | F14: Échéance 07/2026
A15: 46208 | B15: 88664-D-1 | C15: Leasing | D15: 2250 | E15: Wafasalaf LOA | F15: Échéance 07/2026
A16: 46208 | B16: 91702-H-1 | C16: Leasing | D16: 6000 | E16: Wafasalaf LOA | F16: Échéance 07/2026
A17: 46208 | B17: 94626-B-1 | C17: Leasing | D17: 6750 | E17: Wafasalaf LOA | F17: Échéance 07/2026
... A22: 46214 | B22: 74343-B-1 | C22: Réparation | D22: 3000 | E22: Auto Service Hay Riad | F22: Batterie
A23: 46215 | C23: Électricité & eau | D23: 1170 | E23: Redal
A24: 46217 | B24: 94626-B-1 | C24: Carburant | D24: 700 | E24: Afriquia | F24: Plein avant livraison aéroport
A25: 46217 | B25: 94626-B-1 | C25: Réparation | D25: 3400 | E25: Garage Atlas Agdal | F25: Carrosserie
A26: 46218 | C26: Internet & téléphone | D26: 780 | E26: Maroc Telecom | F26: Fibre + 4 lignes
A27: 46219 | B27: 47649-D-1 | C27: Réparation | D27: 2000 | E27: Speedy Rabat | F27: Batterie
A28: 46221 | B28: 76897-B-1 | C28: Carburant | D28: 400 | E28: Afriquia | F28: Plein avant livraison aéroport
A29: 46223 | C29: Marketing | D29: 6100 | E29: Meta Ads / Google Ads | F29: Campagne été
A30: 46228 | C30: Comptabilité | D30: 2500 | E30: Cabinet Fiduciaire
A31: 46229 | B31: 35623-W-1 | C31: Carburant | D31: 400 | E31: Afriquia | F31: Plein avant livraison aéroport
A32: 46229 | B32: 54616-W-1 | C32: Carburant | D32: 600 | E32: Afriquia | F32: Plein avant livraison aéroport
A33: 46231 | C33: Salaires | D33: 40000 | E33: Personnel | F33: 4 agents + renfort été
A34: 46234 | B34: 21066-H-1 | C34: Lavage | D34: 160 | E34: Lavage Express Agdal | F34: 4 lavages
A35: 46234 | B35: 22080-H-1 | C35: Lavage | D35: 160 | E35: Lavage Express Agdal | F35: 4 lavages
A36: 46234 | B36: 22394-A-1 | C36: Lavage | D36: 120 | E36: Lavage Express Agdal | F36: 3 lavages
A37: 46234 | B37: 25835-W-1 | C37: Lavage | D37: 160 | E37: Lavage Express Agdal | F37: 4 lavages
A38: 46234 | B38: 33992-B-1 | C38: Lavage | D38: 120 | E38: Lavage Express Agdal | F38: 3 lavages
A39: 46234 | B39: 35623-W-1 | C39: Lavage | D39: 160 | E39: Lavage Express Agdal | F39: 4 lavages
A40: 46234 | B40: 36193-W-1 | C40: Lavage | D40: 120 | E40: Lavage Express Agdal | F40: 3 lavages
A41: 46234 | B41: 47649-D-1 | C41: Lavage | D41: 160 | E41: Lavage Express Agdal | F41: 4 lavages
A42: 46234 | B42: 49965-H-1 | C42: Lavage | D42: 120 | E42: Lavage Express Agdal | F42: 3 lavages
A43: 46234 | B43: 54616-W-1 | C43: Lavage | D43: 80 | E43: Lavage Express Agdal | F43: 2 lavages
A44: 46234 | B44: 62064-H-1 | C44: Lavage | D44: 160 | E44: Lavage Express Agdal | F44: 4 lavages
...

Sheet RendezVous
A1: DATE | B1: HEURE | C1: TYPE | D1: MATRICULE | E1: CIN | F1: STATUT | G1: NOTE
A2: 46214 | B2: 16:30 | C2: Entretien garage | D2: 25835-W-1 | F2: fait | G2: Révision
A3: 46216 | B3: 14:00 | C3: Rendez-vous client | E3: AB467851 | F3: fait | G3: Mariage — 3 berlines
A4: 46225 | B4: 15:30 | C4: Entretien garage | D4: 97018-A-1 | F4: fait | G4: Révision
A5: 46231 | B5: 16:00 | C5: Visite technique | D5: 21066-H-1 | F5: fait
A6: 46233 | B6: 11:30 | C6: Entretien garage | D6: 91567-W-1 | F6: fait | G6: Révision
A7: 46239 | B7: 11:30 | C7: Fournisseur | F7: fait | G7: Pneus hiver
A8: 46240 | B8: 10:00 | C8: Entretien garage | D8: 23911-A-1 | F8: fait | G8: Révision
A9: 46242 | B9: 16:00 | C9: Rendez-vous client | E9: BE636382 | F9: fait | G9: Contrat entreprise
A10: 46244 | B10: 9:30 | C10: Expertise sinistre | D10: 83373-B-1 | F10: fait | G10: Rayure portière
A11: 46246 | B11: 15:00 | C11: Entretien garage | D11: 33992-B-1 | F11: fait | G11: Révision
A12: 46247 | B12: 14:30 | C12: Fournisseur | F12: fait | G12: Pneus hiver
A13: 46249 | B13: 10:00 | C13: Expertise sinistre | D13: 35623-W-1 | F13: fait | G13: Rayure portière
A14: 46253 | B14: 16:30 | C14: Entretien garage | D14: 69873-A-1 | F14: fait | G14: Révision
A15: 46254 | B15: 15:30 | C15: Entretien garage | D15: 76897-B-1 | F15: fait | G15: Révision
A16: 46256 | B16: 11:00 | C16: Renouvellement assurance | D16: 95936-H-1 | F16: fait
A17: 46259 | B17: 16:00 | C17: Fournisseur | F17: fait | G17: Leasing : 2 citadines
A18: 46265 | B18: 10:30 | C18: Rendez-vous client | E18: AB8443832 | F18: fait | G18: Contrat entreprise
A19: 46267 | B19: 14:00 | C19: Entretien garage | D19: 22080-H-1 | F19: fait | G19: Révision
A20: 46273 | B20: 16:00 | C20: Entretien garage | D20: 91567-W-1 | F20: fait | G20: Révision
A21: 46274 | B21: 9:00 | C21: Entretien garage | D21: 94626-B-1 | F21: fait | G21: Révision
A22: 46283 | B22: 16:30 | C22: Rendez-vous client | E22: AD523795 | F22: fait | G22: Touriste — navette aéroport
A23: 46284 | B23: 15:00 | C23: Rendez-vous client | E23: DA532628 | F23: fait | G23: Contrat entreprise
A24: 46288 | B24: 11:00 | C24: Entretien garage | D24: 75329-D-1 | F24: fait | G24: Révision
A25: 46290 | B25: 11:30 | C25: Entretien garage | D25: 54616-W-1 | F25: prévu | G25: Révision
